Workbook

Sheet Inputs
A1: MONUMENT PARAMETRIC ENGINE -- INPUTS
A2: Self-contained engine workbook. Engine cells filled light green. Custom-scenario input cells filled yellow. Column G ACTIVE is the single live value every downstream sheet reads. Built 2026-05-22.
A3: Active Scenario: | B3: Base
A5: Input | B5: Base | C5: Staged | D5: Compact | E5: Conservation | F5: Custom | G5: ACTIVE | H5: Unit | I5: Notes / source
A6: LOT PROGRAM
A7: Revenue lots | B7: 27 | C7: 27 | D7: 32 | E7: 25 | F7: 27 | G7: =INDEX(B7:F7,MATCH($B$3,$B$5:$F$5,0)) -> 27 | H7: lots | I7: Monetized revenue-producing lots. Drives revenue, Foundation contributions, road band.
A8: Master-plan lots | B8: 50 | C8: 50 | D8: 32 | E8: 25 | F8: 50 | G8: =INDEX(B8:F8,MATCH($B$3,$B$5:$F$5,0)) -> 50 | H8: lots | I8: Total master-plan lots. Drives well cost. Differs from revenue lots in Base/Staged.
A9: Phase 1 lot count | B9: 10 | C9: 10 | D9: 32 | E9: 25 | F9: 27 | G9: =INDEX(B9:F9,MATCH($B$3,$B$5:$F$5,0)) -> 10 | H9: lots | I9: Compact and Conservation are single-phase.
A10: Phase 2 lot count | B10: 12 | C10: 12 | D10: 0 | E10: 0 | F10: 0 | G10: =INDEX(B10:F10,MATCH($B$3,$B$5:$F$5,0)) -> 12 | H10: lots | I10: Zero in single-phase scenarios.
A11: Phase 3 lot count | B11: 5 | C11: 5 | D11: 0 | E11: 0 | F11: 0 | G11: =INDEX(B11:F11,MATCH($B$3,$B$5:$F$5,0)) -> 5 | H11: lots | I11: Phase 1+2+3 must equal Revenue lots.
A12: Project commence year | B12: 2026 | C12: 2026 | D12: 2026 | E12: 2026 | F12: 2026 | G12: =INDEX(B12:F12,MATCH($B$3,$B$5:$F$5,0)) -> 2026 | H12: year | I12: Pro forma commence period.
A14: SALES VELOCITY (lots closing per year)
A15: 2026 | B15: 0 | C15: 0 | D15: 0 | E15: 0 | F15: 0 | G15: =INDEX(B15:F15,MATCH($B$3,$B$5:$F$5,0)) -> 0 | H15: lots | I15: Per-year closings. Base vector from pro forma sales schedule.
A16: 2027 | B16: 1 | C16: 1 | D16: 2 | E16: 0 | F16: 1 | G16: =INDEX(B16:F16,MATCH($B$3,$B$5:$F$5,0)) -> 1 | H16: lots
A17: 2028 | B17: 6 | C17: 6 | D17: 8 | E17: 2 | F17: 6 | G17: =INDEX(B17:F17,MATCH($B$3,$B$5:$F$5,0)) -> 6 | H17: lots
A18: 2029 | B18: 7 | C18: 7 | D18: 10 | E18: 5 | F18: 7 | G18: =INDEX(B18:F18,MATCH($B$3,$B$5:$F$5,0)) -> 7 | H18: lots
A19: 2030 | B19: 9 | C19: 9 | D19: 8 | E19: 7 | F19: 9 | G19: =INDEX(B19:F19,MATCH($B$3,$B$5:$F$5,0)) -> 9 | H19: lots
A20: 2031 | B20: 4 | C20: 4 | D20: 4 | E20: 6 | F20: 4 | G20: =INDEX(B20:F20,MATCH($B$3,$B$5:$F$5,0)) -> 4 | H20: lots
A21: 2032 | B21: 0 | C21: 0 | D21: 0 | E21: 5 | F21: 0 | G21: =INDEX(B21:F21,MATCH($B$3,$B$5:$F$5,0)) -> 0 | H21: lots
A22: Total (must equal Revenue lots) | B22: =SUM(B15:B21) -> 27 | C22: =SUM(C15:C21) -> 27 | D22: =SUM(D15:D21) -> 32 | E22: =SUM(E15:E21) -> 25 | F22: =SUM(F15:F21) -> 27 | G22: =SUM(G15:G21) -> 27 | H22: lots | I22: SUM check against Revenue lots row.
A24: PRICING
A25: Phase 1 lot price ($K) | B25: 5000 | C25: 5500 | D25: 6500 | E25: 7500 | F25: 6500 | G25: =INDEX(B25:F25,MATCH($B$3,$B$5:$F$5,0)) -> 5000 | H25: $K | I25: Gross lot price. Project Summary Q5 cascade.
A26: Phase 2 lot price ($K) | B26: 5500 | C26: 6000 | D26: 0 | E26: 0 | F26: 5500 | G26: =INDEX(B26:F26,MATCH($B$3,$B$5:$F$5,0)) -> 5500 | H26: $K | I26: Zero where Phase 2 count is zero.
A27: Phase 3 lot price ($K) | B27: 6000 | C27: 6500 | D27: 0 | E27: 0 | F27: 6000 | G27: =INDEX(B27:F27,MATCH($B$3,$B$5:$F$5,0)) -> 6000 | H27: $K | I27: Zero where Phase 3 count is zero.
A29: DEVELOPMENT COST -- TIER 1 FIXED
A30: Vertical amenity construction ($K) | B30: 39974.7 | C30: 39974.7 | D30: 39974.7 | E30: 39974.7 | F30: 39974.7 | G30: =INDEX(B30:F30,MATCH($B$3,$B$5:$F$5,0)) -> 39974.7 | H30: $K | I30: Lodge nodes, corrals, fort, amenities, gate. Cost Summary.
A31: Amenity scope multiplier | B31: 1 | C31: 1 | D31: 0.8 | E31: 0.6 | F31: 1 | G31: =INDEX(B31:F31,MATCH($B$3,$B$5:$F$5,0)) -> 1 | H31: x | I31: Scales vertical only. See ENGINE_CHANGELOG Session 2.
A32: Offsite infrastructure ($K) | B32: 2937 | C32: 2937 | D32: 2937 | E32: 2937 | F32: 2937 | G32: =INDEX(B32:F32,MATCH($B$3,$B$5:$F$5,0)) -> 2937 | H32: $K | I32: Faucet Creek roads. Fixed.
A33: Club equipment ($K) | B33: 3514 | C33: 3514 | D33: 3514 | E33: 3514 | F33: 3514 | G33: =INDEX(B33:F33,MATCH($B$3,$B$5:$F$5,0)) -> 3514 | H33: $K | I33: Fixed.
A35: DEVELOPMENT COST -- TIER 2 VARIABLE
A36: Well unit cost ($K/well) | B36: 60 | C36: 60 | D36: 60 | E36: 60 | F36: 60 | G36: =INDEX(B36:F36,MATCH($B$3,$B$5:$F$5,0)) -> 60 | H36: $K | I36: One well per master-plan lot. Team unit cost.
A37: Water rights unit cost ($K/lot) | B37: 30 | C37: 30 | D37: 30 | E37: 30 | F37: 30 | G37: =INDEX(B37:F37,MATCH($B$3,$B$5:$F$5,0)) -> 30 | H37: $K/lot | I37: Per master-plan lot. Team unit cost $30K; see acquisition factor row 91.
A38: In-tract road base mileage | B38: 18.41 | C38: 18.41 | D38: 18.41 | E38: 18.41 | F38: 18.41 | G38: =INDEX(B38:F38,MATCH($B$3,$B$5:$F$5,0)) -> 18.41 | H38: mi | I38: Lower-band mileage. Team base.
A39: Road cost ($K/mile) | B39: 300 | C39: 300 | D39: 300 | E39: 300 | F39: 300 | G39: =INDEX(B39:F39,MATCH($B$3,$B$5:$F$5,0)) -> 300 | H39: $K | I39: Team unit cost.
A40: Road band threshold (lots) | B40: 30 | C40: 30 | D40: 30 | E40: 30 | F40: 30 | G40: =INDEX(B40:F40,MATCH($B$3,$B$5:$F$5,0)) -> 30 | H40: lots | I40: Above this mileage steps up. Deliberate. See Session 2.
A41: Road upper-band uplift | B41: 0.2 | C41: 0.2 | D41: 0.2 | E41: 0.2 | F41: 0.2 | G41: =INDEX(B41:F41,MATCH($B$3,$B$5:$F$5,0)) -> 0.2 | H41: x | I41: Plus 20pct mileage above threshold.
A42: In-tract power ($K) | B42: 2000 | C42: 2000 | D42: 2000 | E42: 2000 | F42: 2000 | G42: =INDEX(B42:F42,MATCH($B$3,$B$5:$F$5,0)) -> 2000 | H42: $K | I42: Fixed within in-tract.
A43: In-tract sewer ($K) | B43: 295 | C43: 295 | D43: 295 | E43: 295 | F43: 295 | G43: =INDEX(B43:F43,MATCH($B$3,$B$5:$F$5,0)) -> 295 | H43: $K | I43: Fixed within in-tract.
A44: In-tract land improvements ($K) | B44: 3750 | C44: 3750 | D44: 3750 | E44: 3750 | F44: 3750 | G44: =INDEX(B44:F44,MATCH($B$3,$B$5:$F$5,0)) -> 3750 | H44: $K | I44: Ski/hunt/ranch. Fixed within in-tract.
A46: DEVELOPMENT COST -- TIER 3 DERIVED
...

Sheet Lot Schedule
A1: MONUMENT PARAMETRIC ENGINE -- LOT SCHEDULE
A2: Parametric replacement for the team per-lot detail rows. Lots fill in strict phase order (Phase 1, then 2, then 3); the annual velocity vector consumes them. All inputs read from the Inputs sheet column G.
A3: Active scenario: | B3: =Inputs!B3 -> Base | D3: Revenue lots: | E3: =Inputs!G7 -> 27 | G3: Sales-velocity factor: | H3: =Inputs!G83 -> 1 | I3: (neutral 1.00; timing-reshape mechanism is an open question, not yet wired)
A5: PHASE DEFINITIONS
A6: Phase | B6: Lot count | C6: Price ($K) | D6: Cum lot start | E6: Cum lot end
A7: Phase 1 | B7: =Inputs!G9 -> 10 | C7: =Inputs!G25 -> 5000 | D7: 1 | E7: =B7 -> 10
A8: Phase 2 | B8: =Inputs!G10 -> 12 | C8: =Inputs!G26 -> 5500 | D8: =E7+1 -> 11 | E8: =E7+B8 -> 22
A9: Phase 3 | B9: =Inputs!G11 -> 5 | C9: =Inputs!G27 -> 6000 | D9: =E8+1 -> 23 | E9: =E8+B9 -> 27
A10: Total | B10: =SUM(B7:B9) -> 27 | E10: =E9 -> 27 | F10: Check vs Revenue lots: | G10: =B10-Inputs!G7 -> 0
A12: ANNUAL LOT SCHEDULE
A13: Year | B13: Lots closing | C13: Cum start | D13: Cum end | E13: P1 lots | F13: P2 lots | G13: P3 lots | H13: Check | I13: P1 rev ($K) | J13: P2 rev ($K) | K13: P3 rev ($K) | L13: Total gross sales ($K) | M13: Cumulative revenue ($K)
A14: 2026 | B14: =Inputs!G15 -> 0 | C14: 0 | D14: =C14+B14 -> 0 | E14: =MAX(0,MIN(D14,$E$7)-MAX(C14+1,$D$7)+1) -> 0 | F14: =MAX(0,MIN(D14,$E$8)-MAX(C14+1,$D$8)+1) -> 0 | G14: =MAX(0,MIN(D14,$E$9)-MAX(C14+1,$D$9)+1) -> 0 | H14: =E14+F14+G14-B14 -> 0 | I14: =E14*$C$7 -> 0 | J14: =F14*$C$8 -> 0 | K14: =G14*$C$9 -> 0 | L14: =I14+J14+K14 -> 0 | M14: =L14 -> 0
A15: 2027 | B15: =Inputs!G16 -> 1 | C15: =D14 -> 0 | D15: =C15+B15 -> 1 | E15: =MAX(0,MIN(D15,$E$7)-MAX(C15+1,$D$7)+1) -> 1 | F15: =MAX(0,MIN(D15,$E$8)-MAX(C15+1,$D$8)+1) -> 0 | G15: =MAX(0,MIN(D15,$E$9)-MAX(C15+1,$D$9)+1) -> 0 | H15: =E15+F15+G15-B15 -> 0 | I15: =E15*$C$7 -> 5000 | J15: =F15*$C$8 -> 0 | K15: =G15*$C$9 -> 0 | L15: =I15+J15+K15 -> 5000 | M15: =M14+L15 -> 5000
A16: 2028 | B16: =Inputs!G17 -> 6 | C16: =D15 -> 1 | D16: =C16+B16 -> 7 | E16: =MAX(0,MIN(D16,$E$7)-MAX(C16+1,$D$7)+1) -> 6 | F16: =MAX(0,MIN(D16,$E$8)-MAX(C16+1,$D$8)+1) -> 0 | G16: =MAX(0,MIN(D16,$E$9)-MAX(C16+1,$D$9)+1) -> 0 | H16: =E16+F16+G16-B16 -> 0 | I16: =E16*$C$7 -> 30000 | J16: =F16*$C$8 -> 0 | K16: =G16*$C$9 -> 0 | L16: =I16+J16+K16 -> 30000 | M16: =M15+L16 -> 35000
A17: 2029 | B17: =Inputs!G18 -> 7 | C17: =D16 -> 7 | D17: =C17+B17 -> 14 | E17: =MAX(0,MIN(D17,$E$7)-MAX(C17+1,$D$7)+1) -> 3 | F17: =MAX(0,MIN(D17,$E$8)-MAX(C17+1,$D$8)+1) -> 4 | G17: =MAX(0,MIN(D17,$E$9)-MAX(C17+1,$D$9)+1) -> 0 | H17: =E17+F17+G17-B17 -> 0 | I17: =E17*$C$7 -> 15000 | J17: =F17*$C$8 -> 22000 | K17: =G17*$C$9 -> 0 | L17: =I17+J17+K17 -> 37000 | M17: =M16+L17 -> 72000
A18: 2030 | B18: =Inputs!G19 -> 9 | C18: =D17 -> 14 | D18: =C18+B18 -> 23 | E18: =MAX(0,MIN(D18,$E$7)-MAX(C18+1,$D$7)+1) -> 0 | F18: =MAX(0,MIN(D18,$E$8)-MAX(C18+1,$D$8)+1) -> 8 | G18: =MAX(0,MIN(D18,$E$9)-MAX(C18+1,$D$9)+1) -> 1 | H18: =E18+F18+G18-B18 -> 0 | I18: =E18*$C$7 -> 0 | J18: =F18*$C$8 -> 44000 | K18: =G18*$C$9 -> 6000 | L18: =I18+J18+K18 -> 50000 | M18: =M17+L18 -> 122000
A19: 2031 | B19: =Inputs!G20 -> 4 | C19: =D18 -> 23 | D19: =C19+B19 -> 27 | E19: =MAX(0,MIN(D19,$E$7)-MAX(C19+1,$D$7)+1) -> 0 | F19: =MAX(0,MIN(D19,$E$8)-MAX(C19+1,$D$8)+1) -> 0 | G19: =MAX(0,MIN(D19,$E$9)-MAX(C19+1,$D$9)+1) -> 4 | H19: =E19+F19+G19-B19 -> 0 | I19: =E19*$C$7 -> 0 | J19: =F19*$C$8 -> 0 | K19: =G19*$C$9 -> 24000 | L19: =I19+J19+K19 -> 24000 | M19: =M18+L19 -> 146000
A20: 2032 | B20: =Inputs!G21 -> 0 | C20: =D19 -> 27 | D20: =C20+B20 -> 27 | E20: =MAX(0,MIN(D20,$E$7)-MAX(C20+1,$D$7)+1) -> 0 | F20: =MAX(0,MIN(D20,$E$8)-MAX(C20+1,$D$8)+1) -> 0 | G20: =MAX(0,MIN(D20,$E$9)-MAX(C20+1,$D$9)+1) -> 0 | H20: =E20+F20+G20-B20 -> 0 | I20: =E20*$C$7 -> 0 | J20: =F20*$C$8 -> 0 | K20: =G20*$C$9 -> 0 | L20: =I20+J20+K20 -> 0 | M20: =M19+L20 -> 146000
A21: 2033 | B21: 0 | C21: =D20 -> 27 | D21: =C21+B21 -> 27 | E21: =MAX(0,MIN(D21,$E$7)-MAX(C21+1,$D$7)+1) -> 0 | F21: =MAX(0,MIN(D21,$E$8)-MAX(C21+1,$D$8)+1) -> 0 | G21: =MAX(0,MIN(D21,$E$9)-MAX(C21+1,$D$9)+1) -> 0 | H21: =E21+F21+G21-B21 -> 0 | I21: =E21*$C$7 -> 0 | J21: =F21*$C$8 -> 0 | K21: =G21*$C$9 -> 0 | L21: =I21+J21+K21 -> 0 | M21: =M20+L21 -> 146000
A22: 2034 | B22: 0 | C22: =D21 -> 27 | D22: =C22+B22 -> 27 | E22: =MAX(0,MIN(D22,$E$7)-MAX(C22+1,$D$7)+1) -> 0 | F22: =MAX(0,MIN(D22,$E$8)-MAX(C22+1,$D$8)+1) -> 0 | G22: =MAX(0,MIN(D22,$E$9)-MAX(C22+1,$D$9)+1) -> 0 | H22: =E22+F22+G22-B22 -> 0 | I22: =E22*$C$7 -> 0 | J22: =F22*$C$8 -> 0 | K22: =G22*$C$9 -> 0 | L22: =I22+J22+K22 -> 0 | M22: =M21+L22 -> 146000
A23: 2035 | B23: 0 | C23: =D22 -> 27 | D23: =C23+B23 -> 27 | E23: =MAX(0,MIN(D23,$E$7)-MAX(C23+1,$D$7)+1) -> 0 | F23: =MAX(0,MIN(D23,$E$8)-MAX(C23+1,$D$8)+1) -> 0 | G23: =MAX(0,MIN(D23,$E$9)-MAX(C23+1,$D$9)+1) -> 0 | H23: =E23+F23+G23-B23 -> 0 | I23: =E23*$C$7 -> 0 | J23: =F23*$C$8 -> 0 | K23: =G23*$C$9 -> 0 | L23: =I23+J23+K23 -> 0 | M23: =M22+L23 -> 146000
A24: 2036 | B24: 0 | C24: =D23 -> 27 | D24: =C24+B24 -> 27 | E24: =MAX(0,MIN(D24,$E$7)-MAX(C24+1,$D$7)+1) -> 0 | F24: =MAX(0,MIN(D24,$E$8)-MAX(C24+1,$D$8)+1) -> 0 | G24: =MAX(0,MIN(D24,$E$9)-MAX(C24+1,$D$9)+1) -> 0 | H24: =E24+F24+G24-B24 -> 0 | I24: =E24*$C$7 -> 0 | J24: =F24*$C$8 -> 0 | K24: =G24*$C$9 -> 0 | L24: =I24+J24+K24 -> 0 | M24: =M23+L24 -> 146000
A25: 2037 | B25: 0 | C25: =D24 -> 27 | D25: =C25+B25 -> 27 | E25: =MAX(0,MIN(D25,$E$7)-MAX(C25+1,$D$7)+1) -> 0 | F25: =MAX(0,MIN(D25,$E$8)-MAX(C25+1,$D$8)+1) -> 0 | G25: =MAX(0,MIN(D25,$E$9)-MAX(C25+1,$D$9)+1) -> 0 | H25: =E25+F25+G25-B25 -> 0 | I25: =E25*$C$7 -> 0 | J25: =F25*$C$8 -> 0 | K25: =G25*$C$9 -> 0 | L25: =I25+J25+K25 -> 0 | M25: =M24+L25 -> 146000
A26: Total | B26: =SUM(B14:B25) -> 27 | E26: =SUM(E14:E25) -> 10 | F26: =SUM(F14:F25) -> 12 | G26: =SUM(G14:G25) -> 5 | H26: =SUM(H14:H25) -> 0 | I26: =SUM(I14:I25) -> 50000 | J26: =SUM(J14:J25) -> 66000 | K26: =SUM(K14:K25) -> 30000 | L26: =SUM(L14:L25) -> 146000 | M26: =M25 -> 146000

Sheet Revenue
A1: MONUMENT PARAMETRIC ENGINE -- REVENUE
A2: Real estate sales, Foundation contributions, initiation fees, and club dues by year. Gross real estate sales is headline #1. Inputs read from Inputs column G; lot flow from the Lot Schedule.
A3: Active scenario: | B3: =Inputs!B3 -> Base
A5: REVENUE SUMMARY
A6: Metric | B6: Engine total ($K) | C6: Team ($K) | D6: Delta | E6: Note
A7: Gross real estate sales | B7: =C29 -> 146000 | C7: 146000 | D7: =B7-C7 -> 0 | E7: HEADLINE #1
A8: Selling costs | B8: =D29 -> 4745 | C8: 4745 | D8: =B8-C8 -> 0 | E8: Commission 3% + closing
A9: Net real estate proceeds | B9: =E29 -> 141255 | C9: 141255 | D9: =B9-C9 -> 0 | E9: Ties to Real Estate Sales NET LOT SALES line
A10: Foundation contributions | B10: =F29 -> 32400 | C10: 32400 | D10: =B10-C10 -> 0 | E10: Lots x per-lot contribution
A11: Initiation fees (net) | B11: =J29 -> 8860.5 | C11: 8860.5 | D11: =B11-C11 -> 0 | E11: Gross 8950 less 1% reconciling adj
A12: Club dues | B12: =M29 -> 17451.25 | C12: 17451.25 | D12: =B12-C12 -> 0 | E12: Calibrated to team member roster
A14: ANNUAL DETAIL
A15: Columns G, H, K, L are calibration constants from the team membership roster (activation timing). All other columns are formulas. Calibration columns will be regenerated per scenario at expansion.
A16: Year | B16: Lots closing | C16: Gross RE sales ($K) | D16: Selling costs ($K) | E16: Net RE proceeds ($K) | F16: Foundation contrib ($K) | G16: Ranch IF joins | H16: Social IF joins | I16: IF gross ($K) | J16: IF net ($K) | K16: Ranch mbr-months | L16: Social mbr-months | M16: Club dues ($K)
A17: 2026 | B17: ='Lot Schedule'!B14 -> 0 | C17: ='Lot Schedule'!L14 -> 0 | D17: =C17*Inputs!$G$88+Inputs!$G$89*B17/Inputs!$G$7 -> 0 | E17: =C17-D17 -> 0 | F17: =B17*Inputs!$G$51 -> 0 | G17: 0 | H17: 0 | I17: =G17/SUM($G$17:$G$28)*Inputs!$G$7*Inputs!$G$77+H17/SUM($H$17:$H$28)*Inputs!$G$74*Inputs!$G$78 -> 0 | J17: =I17*(1-Inputs!$G$90) -> 0 | K17: 160 | L17: 0 | M17: =K17/12*((15+Inputs!$G$7)/42)*Inputs!$G$75+L17/12*(Inputs!$G$74/50)*Inputs!$G$76 -> 333.33333
A18: 2027 | B18: ='Lot Schedule'!B15 -> 1 | C18: ='Lot Schedule'!L15 -> 5000 | D18: =C18*Inputs!$G$88+Inputs!$G$89*B18/Inputs!$G$7 -> 163.51852 | E18: =C18-D18 -> 4836.4815 | F18: =B18*Inputs!$G$51 -> 1200 | G18: 1 | H18: 18 | I18: =G18/SUM($G$17:$G$28)*Inputs!$G$7*Inputs!$G$77+H18/SUM($H$17:$H$28)*Inputs!$G$74*Inputs!$G$78 -> 2350 | J18: =I18*(1-Inputs!$G$90) -> 2326.5 | K18: 181 | L18: 91 | M18: =K18/12*((15+Inputs!$G$7)/42)*Inputs!$G$75+L18/12*(Inputs!$G$74/50)*Inputs!$G$76 -> 490.83333
A19: 2028 | B19: ='Lot Schedule'!B16 -> 6 | C19: ='Lot Schedule'!L16 -> 30000 | D19: =C19*Inputs!$G$88+Inputs!$G$89*B19/Inputs!$G$7 -> 981.11111 | E19: =C19-D19 -> 29018.889 | F19: =B19*Inputs!$G$51 -> 7200 | G19: 7 | H19: 24 | I19: =G19/SUM($G$17:$G$28)*Inputs!$G$7*Inputs!$G$77+H19/SUM($H$17:$H$28)*Inputs!$G$74*Inputs!$G$78 -> 3700 | J19: =I19*(1-Inputs!$G$90) -> 3663 | K19: 243 | L19: 372 | M19: =K19/12*((15+Inputs!$G$7)/42)*Inputs!$G$75+L19/12*(Inputs!$G$74/50)*Inputs!$G$76 -> 971.25
A20: 2029 | B20: ='Lot Schedule'!B17 -> 7 | C20: ='Lot Schedule'!L17 -> 37000 | D20: =C20*Inputs!$G$88+Inputs!$G$89*B20/Inputs!$G$7 -> 1204.6296 | E20: =C20-D20 -> 35795.37 | F20: =B20*Inputs!$G$51 -> 8400 | G20: 8 | H20: 8 | I20: =G20/SUM($G$17:$G$28)*Inputs!$G$7*Inputs!$G$77+H20/SUM($H$17:$H$28)*Inputs!$G$74*Inputs!$G$78 -> 1800 | J20: =I20*(1-Inputs!$G$90) -> 1782 | K20: 330 | L20: 588 | M20: =K20/12*((15+Inputs!$G$7)/42)*Inputs!$G$75+L20/12*(Inputs!$G$74/50)*Inputs!$G$76 -> 1422.5
A21: 2030 | B21: ='Lot Schedule'!B18 -> 9 | C21: ='Lot Schedule'!L18 -> 50000 | D21: =C21*Inputs!$G$88+Inputs!$G$89*B21/Inputs!$G$7 -> 1621.6667 | E21: =C21-D21 -> 48378.333 | F21: =B21*Inputs!$G$51 -> 10800 | G21: 8 | H21: 0 | I21: =G21/SUM($G$17:$G$28)*Inputs!$G$7*Inputs!$G$77+H21/SUM($H$17:$H$28)*Inputs!$G$74*Inputs!$G$78 -> 800 | J21: =I21*(1-Inputs!$G$90) -> 792 | K21: 433 | L21: 600 | M21: =K21/12*((15+Inputs!$G$7)/42)*Inputs!$G$75+L21/12*(Inputs!$G$74/50)*Inputs!$G$76 -> 1652.0833
A22: 2031 | B22: ='Lot Schedule'!B19 -> 4 | C22: ='Lot Schedule'!L19 -> 24000 | D22: =C22*Inputs!$G$88+Inputs!$G$89*B22/Inputs!$G$7 -> 774.07407 | E22: =C22-D22 -> 23225.926 | F22: =B22*Inputs!$G$51 -> 4800 | G22: 3 | H22: 0 | I22: =G22/SUM($G$17:$G$28)*Inputs!$G$7*Inputs!$G$77+H22/SUM($H$17:$H$28)*Inputs!$G$74*Inputs!$G$78 -> 300 | J22: =I22*(1-Inputs!$G$90) -> 297 | K22: 495 | L22: 600 | M22: =K22/12*((15+Inputs!$G$7)/42)*Inputs!$G$75+L22/12*(Inputs!$G$74/50)*Inputs!$G$76 -> 1781.25
A23: 2032 | B23: ='Lot Schedule'!B20 -> 0 | C23: ='Lot Schedule'!L20 -> 0 | D23: =C23*Inputs!$G$88+Inputs!$G$89*B23/Inputs!$G$7 -> 0 | E23: =C23-D23 -> 0 | F23: =B23*Inputs!$G$51 -> 0 | G23: 0 | H23: 0 | I23: =G23/SUM($G$17:$G$28)*Inputs!$G$7*Inputs!$G$77+H23/SUM($H$17:$H$28)*Inputs!$G$74*Inputs!$G$78 -> 0 | J23: =I23*(1-Inputs!$G$90) -> 0 | K23: 504 | L23: 600 | M23: =K23/12*((15+Inputs!$G$7)/42)*Inputs!$G$75+L23/12*(Inputs!$G$74/50)*Inputs!$G$76 -> 1800
A24: 2033 | B24: ='Lot Schedule'!B21 -> 0 | C24: ='Lot Schedule'!L21 -> 0 | D24: =C24*Inputs!$G$88+Inputs!$G$89*B24/Inputs!$G$7 -> 0 | E24: =C24-D24 -> 0 | F24: =B24*Inputs!$G$51 -> 0 | G24: 0 | H24: 0 | I24: =G24/SUM($G$17:$G$28)*Inputs!$G$7*Inputs!$G$77+H24/SUM($H$17:$H$28)*Inputs!$G$74*Inputs!$G$78 -> 0 | J24: =I24*(1-Inputs!$G$90) -> 0 | K24: 504 | L24: 600 | M24: =K24/12*((15+Inputs!$G$7)/42)*Inputs!$G$75+L24/12*(Inputs!$G$74/50)*Inputs!$G$76 -> 1800
A25: 2034 | B25: ='Lot Schedule'!B22 -> 0 | C25: ='Lot Schedule'!L22 -> 0 | D25: =C25*Inputs!$G$88+Inputs!$G$89*B25/Inputs!$G$7 -> 0 | E25: =C25-D25 -> 0 | F25: =B25*Inputs!$G$51 -> 0 | G25: 0 | H25: 0 | I25: =G25/SUM($G$17:$G$28)*Inputs!$G$7*Inputs!$G$77+H25/SUM($H$17:$H$28)*Inputs!$G$74*Inputs!$G$78 -> 0 | J25: =I25*(1-Inputs!$G$90) -> 0 | K25: 504 | L25: 600 | M25: =K25/12*((15+Inputs!$G$7)/42)*Inputs!$G$75+L25/12*(Inputs!$G$74/50)*Inputs!$G$76 -> 1800
A26: 2035 | B26: ='Lot Schedule'!B23 -> 0 | C26: ='Lot Schedule'!L23 -> 0 | D26: =C26*Inputs!$G$88+Inputs!$G$89*B26/Inputs!$G$7 -> 0 | E26: =C26-D26 -> 0 | F26: =B26*Inputs!$G$51 -> 0 | G26: 0 | H26: 0 | I26: =G26/SUM($G$17:$G$28)*Inputs!$G$7*Inputs!$G$77+H26/SUM($H$17:$H$28)*Inputs!$G$74*Inputs!$G$78 -> 0 | J26: =I26*(1-Inputs!$G$90) -> 0 | K26: 504 | L26: 600 | M26: =K26/12*((15+Inputs!$G$7)/42)*Inputs!$G$75+L26/12*(Inputs!$G$74/50)*Inputs!$G$76 -> 1800
A27: 2036 | B27: ='Lot Schedule'!B24 -> 0 | C27: ='Lot Schedule'!L24 -> 0 | D27: =C27*Inputs!$G$88+Inputs!$G$89*B27/Inputs!$G$7 -> 0 | E27: =C27-D27 -> 0 | F27: =B27*Inputs!$G$51 -> 0 | G27: 0 | H27: 0 | I27: =G27/SUM($G$17:$G$28)*Inputs!$G$7*Inputs!$G$77+H27/SUM($H$17:$H$28)*Inputs!$G$74*Inputs!$G$78 -> 0 | J27: =I27*(1-Inputs!$G$90) -> 0 | K27: 504 | L27: 600 | M27: =K27/12*((15+Inputs!$G$7)/42)*Inputs!$G$75+L27/12*(Inputs!$G$74/50)*Inputs!$G$76 -> 1800
A28: 2037 | B28: ='Lot Schedule'!B25 -> 0 | C28: ='Lot Schedule'!L25 -> 0 | D28: =C28*Inputs!$G$88+Inputs!$G$89*B28/Inputs!$G$7 -> 0 | E28: =C28-D28 -> 0 | F28: =B28*Inputs!$G$51 -> 0 | G28: 0 | H28: 0 | I28: =G28/SUM($G$17:$G$28)*Inputs!$G$7*Inputs!$G$77+H28/SUM($H$17:$H$28)*Inputs!$G$74*Inputs!$G$78 -> 0 | J28: =I28*(1-Inputs!$G$90) -> 0 | K28: 504 | L28: 600 | M28: =K28/12*((15+Inputs!$G$7)/42)*Inputs!$G$75+L28/12*(Inputs!$G$74/50)*Inputs!$G$76 -> 1800
A29: Total | B29: =SUM(B17:B28) -> 27 | C29: =SUM(C17:C28) -> 146000 | D29: =SUM(D17:D28) -> 4745 | E29: =SUM(E17:E28) -> 141255 | F29: =SUM(F17:F28) -> 32400 | G29: =SUM(G17:G28) -> 27 | H29: =SUM(H17:H28) -> 50 | I29: =SUM(I17:I28) -> 8950 | ... M29: =SUM(M17:M28) -> 17451.25

Sheet Development Cost
A1: MONUMENT PARAMETRIC ENGINE -- DEVELOPMENT COST
A2: Three-tier construction cost model. Tier 1 fixed amenities scaled by amenity scope multiplier; Tier 2 variable wells/water/road; Tier 3 derived fees. Reconciliation target: team Project & Constr. Cost $67,403.7K.
A3: Active scenario: | B3: =Inputs!B3 -> Base
A5: THREE-TIER COST MODEL
A6: Component | B6: Amount ($K) | C6: Basis | D6: Note
A7: Tier 1 -- Fixed
A8: Vertical amenity construction | B8: =Inputs!G30*Inputs!G31 -> 39974.7 | C8: vertical x amenity scope mult | D8: Lodge nodes, corrals, fort, amenities, gate
A9: Offsite infrastructure | B9: =Inputs!G32 -> 2937 | C9: fixed | D9: Faucet Creek roads
A10: Club equipment | B10: =Inputs!G33 -> 3514 | C10: fixed | D10: Not in mgmt-fee/contingency base
A11: Tier 1 subtotal | B11: =SUM(B8:B10) -> 46425.7
A12: Tier 2 -- Variable
A13: Wells | B13: =Inputs!G36*Inputs!G8 -> 3000 | C13: well unit cost x master-plan lots | D13: One well per master-plan lot
A14: Water rights | B14: =Inputs!G37*Inputs!G8*Inputs!G91 -> 750 | C14: unit cost x master-plan lots x 0.5 | D14: Acquisition factor 0.5; see Inputs row 91
A15: In-tract roads | B15: =IF(Inputs!G7>Inputs!G40,Inputs!G38*(1+Inputs!G41),Inputs!G38)*Inputs!G39 -> 5523 | C15: band logic x road cost/mile | D15: Base 18.41 mi; +20pct above 30 revenue lots
A16: In-tract power | B16: =Inputs!G42 -> 2000 | C16: fixed
A17: In-tract sewer | B17: =Inputs!G43 -> 295 | C17: fixed
A18: In-tract land improvements | B18: =Inputs!G44 -> 3750 | C18: fixed | D18: Ski / hunt / ranch
A19: Tier 2 subtotal | B19: =SUM(B13:B18) -> 15318
A20: Tier 3 -- Derived
A21: Project + infrastructure base | B21: =B8+B9+B19 -> 58229.7 | C21: vertical+offsite+Tier2 | D21: Excludes club equipment, per team structure
A22: Management fees | B22: =B21*Inputs!G47 -> 3159.9453 | C22: base x 5.4267pct
A23: Contingency | B23: =B21*Inputs!G48 -> 2499.9565 | C23: base x 4.2933pct
A24: Tier 3 subtotal | B24: =B22+B23 -> 5659.9018
A26: TOTAL DEVELOPMENT COST | B26: =B11+B19+B24 -> 67403.602
A27: Team Project & Constr. Cost | B27: 67403.72
A28: Delta (engine - team) | B28: =B26-B27 -> -0.11819877
A30: ANNUAL PHASING
A31: Phases the three-tier total by the team overall development-cost curve (Cash Flow Summary), normalized. NOTE: the team Total Development Cost in the cash flow is $100,999.84K and includes pre-development and sales & marketing not in the three-tier model. The construction-vs-total gap and final phasing are resolved at the Cash Flow sheet.
A32: Year | B32: Phasing share | C32: Development cost ($K)
A33: 2026 | B33: 0.0443134 | C33: =B33*$B$26 -> 2986.8828
A34: 2027 | B34: 0.0869597 | C34: =B34*$B$26 -> 5861.397
A35: 2028 | B35: 0.1737154 | C35: =B35*$B$26 -> 11709.044
A36: 2029 | B36: 0.2466928 | C36: =B36*$B$26 -> 16627.983
A37: 2030 | B37: 0.2605279 | C37: =B37*$B$26 -> 17560.519
A38: 2031 | B38: 0.1831452 | C38: =B38*$B$26 -> 12344.646
A39: 2032 | B39: 0.0046458 | C39: =B39*$B$26 -> 313.14365
A40: 2033 | B40: 0 | C40: =B40*$B$26 -> 0
A41: 2034 | B41: 0 | C41: =B41*$B$26 -> 0
A42: 2035 | B42: 0 | C42: =B42*$B$26 -> 0
A43: 2036 | B43: 0 | C43: =B43*$B$26 -> 0
...

Sheet Foundation
A1: MONUMENT PARAMETRIC ENGINE -- FOUNDATION
A2: Foundation fund annual roll-forward with a tightened intra-year convention mirroring the team monthly-compounding model. Reconciliation target: end balance 2037 = $33,525K.
A3: Active scenario: | B3: =Inputs!B3 -> Base
A5: FOUNDATION SUMMARY
A6: Metric | B6: Engine ($K) | C6: Team ($K) | D6: Delta | E6: Note
A7: End fund balance 2037 | B7: =H31 -> 33348.428 | C7: 33525.16 | D7: =B7-C7 -> -176.73185 | E7: HEADLINE #5
A8: Total lot contributions | B8: =SUM(C20:C31) -> 32400 | C8: 32400 | D8: =B8-C8 -> 0
A9: Total grants | B9: =SUM(D20:D31) -> 4937.5 | C9: 4937.5 | D9: =B9-C9 -> 0
A10: Total Foundation expenses | B10: =SUM(E20:E31) -> -23776.35 | C10: -23776.35 | D10: =B10-C10 -> 0
A11: Total investment yield | B11: =SUM(G20:G31) -> 18787.278 | C11: 18964.01 | D11: =B11-C11 -> -176.73185
A13: INTRA-YEAR TIMING CONVENTION (TIGHTENED)
A14: Contributions and grants at mid-year (0.5 weight). Expenses paid evenly, return-before-expense sequencing (0.458 weight). Yield on average balance at the monthly-effective annual rate. Contributions recognized on the team contract-led schedule.
A15: Effective annual yield rate | B15: =(1+Inputs!G52/12)^12-1 -> 0.072290081 | C15: monthly compounding of the Inputs yield rate
A16: Expense weight | B16: 0.458 | C16: return-before-expense monthly sequencing
A18: ANNUAL ROLL-FORWARD
A19: Year | B19: Begin balance | C19: Lot contributions | D19: Grants | E19: Foundation expenses | F19: Average balance | G19: Investment yield | H19: End balance | I19: Contribution recognition (lots) | J19: Expense calib base | K19: Grant ramp factor
A20: 2026 | B20: =Inputs!G92 -> 1000 | C20: =I20/SUM($I$20:$I$31)*Inputs!$G$7*Inputs!$G$51 -> 0 | D20: =Inputs!$G$53*K20 -> 0 | E20: =-J20*(Inputs!$G$54/0.6) -> -542.9 | F20: =B20+0.5*C20+0.5*D20+$B$16*E20 -> 751.3518 | G20: =$B$15*F20 -> 54.315282 | H20: =B20+C20+D20+E20+G20 -> 511.41528 | I20: 0 | J20: 542.9 | K20: 0
A21: 2027 | B21: =H20 -> 511.41528 | C21: =I21/SUM($I$20:$I$31)*Inputs!$G$7*Inputs!$G$51 -> 2400 | D21: =Inputs!$G$53*K21 -> 62.5 | E21: =-J21*(Inputs!$G$54/0.6) -> -515.75 | F21: =B21+0.5*C21+0.5*D21+$B$16*E21 -> 1506.4518 | G21: =$B$15*F21 -> 108.90152 | H21: =B21+C21+D21+E21+G21 -> 2567.0668 | I21: 2 | J21: 515.75 | K21: 0.125
A22: 2028 | B22: =H21 -> 2567.0668 | C22: =I22/SUM($I$20:$I$31)*Inputs!$G$7*Inputs!$G$51 -> 7200 | D22: =Inputs!$G$53*K22 -> 375 | E22: =-J22*(Inputs!$G$54/0.6) -> -1353.55 | F22: =B22+0.5*C22+0.5*D22+$B$16*E22 -> 5734.6409 | G22: =$B$15*F22 -> 414.55765 | H22: =B22+C22+D22+E22+G22 -> 9203.0745 | I22: 6 | J22: 1353.55 | K22: 0.75
A23: 2029 | B23: =H22 -> 9203.0745 | C23: =I23/SUM($I$20:$I$31)*Inputs!$G$7*Inputs!$G$51 -> 8400 | D23: =Inputs!$G$53*K23 -> 500 | E23: =-J23*(Inputs!$G$54/0.6) -> -1712.45 | F23: =B23+0.5*C23+0.5*D23+$B$16*E23 -> 12868.772 | G23: =$B$15*F23 -> 930.28459 | H23: =B23+C23+D23+E23+G23 -> 17320.909 | I23: 7 | J23: 1712.45 | K23: 1
A24: 2030 | B24: =H23 -> 17320.909 | C24: =I24/SUM($I$20:$I$31)*Inputs!$G$7*Inputs!$G$51 -> 9600 | D24: =Inputs!$G$53*K24 -> 500 | E24: =-J24*(Inputs!$G$54/0.6) -> -2137.89 | F24: =B24+0.5*C24+0.5*D24+$B$16*E24 -> 21391.755 | G24: =$B$15*F24 -> 1546.4117 | H24: =B24+C24+D24+E24+G24 -> 26829.431 | I24: 8 | J24: 2137.89 | K24: 1
A25: 2031 | B25: =H24 -> 26829.431 | C25: =I25/SUM($I$20:$I$31)*Inputs!$G$7*Inputs!$G$51 -> 4800 | D25: =Inputs!$G$53*K25 -> 500 | E25: =-J25*(Inputs!$G$54/0.6) -> -2404.05 | F25: =B25+0.5*C25+0.5*D25+$B$16*E25 -> 28378.376 | G25: =$B$15*F25 -> 2051.4751 | H25: =B25+C25+D25+E25+G25 -> 31776.856 | I25: 4 | J25: 2404.05 | K25: 1
A26: 2032 | B26: =H25 -> 31776.856 | C26: =I26/SUM($I$20:$I$31)*Inputs!$G$7*Inputs!$G$51 -> 0 | D26: =Inputs!$G$53*K26 -> 500 | E26: =-J26*(Inputs!$G$54/0.6) -> -2461.16 | F26: =B26+0.5*C26+0.5*D26+$B$16*E26 -> 30899.645 | G26: =$B$15*F26 -> 2233.7378 | H26: =B26+C26+D26+E26+G26 -> 32049.434 | I26: 0 | J26: 2461.16 | K26: 1
A27: 2033 | B27: =H26 -> 32049.434 | C27: =I27/SUM($I$20:$I$31)*Inputs!$G$7*Inputs!$G$51 -> 0 | D27: =Inputs!$G$53*K27 -> 500 | E27: =-J27*(Inputs!$G$54/0.6) -> -2483.12 | F27: =B27+0.5*C27+0.5*D27+$B$16*E27 -> 31162.165 | G27: =$B$15*F27 -> 2252.7154 | H27: =B27+C27+D27+E27+G27 -> 32319.029 | I27: 0 | J27: 2483.12 | K27: 1
A28: 2034 | B28: =H27 -> 32319.029 | C28: =I28/SUM($I$20:$I$31)*Inputs!$G$7*Inputs!$G$51 -> 0 | D28: =Inputs!$G$53*K28 -> 500 | E28: =-J28*(Inputs!$G$54/0.6) -> -2505.73 | F28: =B28+0.5*C28+0.5*D28+$B$16*E28 -> 31421.405 | G28: =$B$15*F28 -> 2271.4559 | H28: =B28+C28+D28+E28+G28 -> 32584.755 | I28: 0 | J28: 2505.73 | K28: 1
A29: 2035 | B29: =H28 -> 32584.755 | C29: =I29/SUM($I$20:$I$31)*Inputs!$G$7*Inputs!$G$51 -> 0 | D29: =Inputs!$G$53*K29 -> 500 | E29: =-J29*(Inputs!$G$54/0.6) -> -2529.02 | F29: =B29+0.5*C29+0.5*D29+$B$16*E29 -> 31676.464 | G29: =$B$15*F29 -> 2289.8941 | H29: =B29+C29+D29+E29+G29 -> 32845.629 | I29: 0 | J29: 2529.02 | K29: 1
A30: 2036 | B30: =H29 -> 32845.629 | C30: =I30/SUM($I$20:$I$31)*Inputs!$G$7*Inputs!$G$51 -> 0 | D30: =Inputs!$G$53*K30 -> 500 | E30: =-J30*(Inputs!$G$54/0.6) -> -2553.01 | F30: =B30+0.5*C30+0.5*D30+$B$16*E30 -> 31926.351 | G30: =$B$15*F30 -> 2307.9585 | H30: =B30+C30+D30+E30+G30 -> 33100.578 | I30: 0 | J30: 2553.01 | K30: 1
A31: 2037 | B31: =H30 -> 33100.578 | C31: =I31/SUM($I$20:$I$31)*Inputs!$G$7*Inputs!$G$51 -> 0 | D31: =Inputs!$G$53*K31 -> 500 | E31: =-J31*(Inputs!$G$54/0.6) -> -2577.72 | F31: =B31+0.5*C31+0.5*D31+$B$16*E31 -> 32169.982 | G31: =$B$15*F31 -> 2325.5706 | H31: =B31+C31+D31+E31+G31 -> 33348.428 | I31: 0 | J31: 2577.72 | K31: 1
A32: Total | C32: =SUM(C20:C31) -> 32400 | D32: =SUM(D20:D31) -> 4937.5 | E32: =SUM(E20:E31) -> -23776.35 | G32: =SUM(G20:G31) -> 18787.278 | H32: =H31 -> 33348.428 | I32: =SUM(I20:I31) -> 27

Sheet Debt
A1: MONUMENT PARAMETRIC ENGINE -- DEBT
A2: Pre-existing debt (La Plata + Swans). Amortization built from loan terms by PMT, not from the team Pre-Existing Debt sheet (which carries Lotus-import #REF! errors). Annual amortization for the annual engine. Both balloon paths computed; the Cash Flow sheet selects.
A3: Active scenario: | B3: =Inputs!B3 -> Base
A5: LOAN TERMS
A6: Loan | B6: Principal ($K) | C6: Annual rate | D6: Amort years | E6: Term years | F6: Annual payment ($K)
A7: La Plata | B7: 11000 | C7: 0.06 | D7: 20 | E7: 6 | F7: =PMT(C7,D7,-B7) -> 959.03013
A8: Swans | B8: 13000 | C8: 0.04 | D8: 30 | E8: 6 | F8: =PMT(C8,D8,-B8) -> 751.79129
A9: Refinance rate (balloon, both loans) | B9: =Inputs!G66 -> 0.075
A10: Origination Sept 2026; 6 annual payments 2026-2031; balloon Sept 2032.
A12: LA PLATA -- AMORTIZATION (ORIGINAL 6-YEAR TERM)
A13: Year | B13: Begin balance | C13: Interest | D13: Payment | E13: Principal | F13: End balance
A14: 2026 | B14: =$B$7 -> 11000 | C14: =B14*$C$7 -> 660 | D14: =$F$7 -> 959.03013 | E14: =D14-C14 -> 299.03013 | F14: =B14-E14 -> 10700.97
A15: 2027 | B15: =F14 -> 10700.97 | C15: =B15*$C$7 -> 642.05819 | D15: =$F$7 -> 959.03013 | E15: =D15-C15 -> 316.97193 | F15: =B15-E15 -> 10383.998
A16: 2028 | B16: =F15 -> 10383.998 | C16: =B16*$C$7 -> 623.03988 | D16: =$F$7 -> 959.03013 | E16: =D16-C16 -> 335.99025 | F16: =B16-E16 -> 10048.008
A17: 2029 | B17: =F16 -> 10048.008 | C17: =B17*$C$7 -> 602.88046 | D17: =$F$7 -> 959.03013 | E17: =D17-C17 -> 356.14967 | F17: =B17-E17 -> 9691.858
A18: 2030 | B18: =F17 -> 9691.858 | C18: =B18*$C$7 -> 581.51148 | D18: =$F$7 -> 959.03013 | E18: =D18-C18 -> 377.51865 | F18: =B18-E18 -> 9314.3394
A19: 2031 | B19: =F18 -> 9314.3394 | C19: =B19*$C$7 -> 558.86036 | D19: =$F$7 -> 959.03013 | E19: =D19-C19 -> 400.16976 | F19: =B19-E19 -> 8914.1696
A21: SWANS -- AMORTIZATION (ORIGINAL 6-YEAR TERM)
A22: Year | B22: Begin balance | C22: Interest | D22: Payment | E22: Principal | F22: End balance
A23: 2026 | B23: =$B$8 -> 13000 | C23: =B23*$C$8 -> 520 | D23: =$F$8 -> 751.79129 | E23: =D23-C23 -> 231.79129 | F23: =B23-E23 -> 12768.209
A24: 2027 | B24: =F23 -> 12768.209 | C24: =B24*$C$8 -> 510.72835 | D24: =$F$8 -> 751.79129 | E24: =D24-C24 -> 241.06294 | F24: =B24-E24 -> 12527.146
A25: 2028 | B25: =F24 -> 12527.146 | C25: =B25*$C$8 -> 501.08583 | D25: =$F$8 -> 751.79129 | E25: =D25-C25 -> 250.70546 | F25: =B25-E25 -> 12276.44
A26: 2029 | B26: =F25 -> 12276.44 | C26: =B26*$C$8 -> 491.05761 | D26: =$F$8 -> 751.79129 | E26: =D26-C26 -> 260.73368 | F26: =B26-E26 -> 12015.707
A27: 2030 | B27: =F26 -> 12015.707 | C27: =B27*$C$8 -> 480.62827 | D27: =$F$8 -> 751.79129 | E27: =D27-C27 -> 271.16302 | F27: =B27-E27 -> 11744.544
A28: 2031 | B28: =F27 -> 11744.544 | C28: =B28*$C$8 -> 469.78174 | D28: =$F$8 -> 751.79129 | E28: =D28-C28 -> 282.00954 | F28: =B28-E28 -> 11462.534
A30: BALLOON AT SEPTEMBER 2032
A31: La Plata balloon | B31: =F19 -> 8914.1696
A32: Swans balloon | B32: =F28 -> 11462.534
A33: Combined balloon | B33: =B31+B32 -> 20376.704
A35: REFINANCE PATH -- BALLOON REFINANCED AT 7.5%
A36: Loan | B36: Balloon ($K) | C36: Refi rate | D36: Refi amort years | E36: Annual payment ($K)
A37: La Plata | B37: =B31 -> 8914.1696 | C37: =$B$9 -> 0.075 | D37: =D7-E7 -> 14 | E37: =PMT(C37,D37,-B37) -> 1050.0658
A38: Swans | B38: =B32 -> 11462.534 | C38: =$B$9 -> 0.075 | D38: =D8-E8 -> 24 | E38: =PMT(C38,D38,-B38) -> 1043.6646
A40: COMBINED ANNUAL DEBT SERVICE -- BOTH BALLOON PATHS
A41: Year | B41: La Plata (retire) | C41: Swans (retire) | D41: Retire path total | E41: La Plata (refi) | F41: Swans (refi) | G41: Refinance path total
A42: 2026 | B42: =$F$7 -> 959.03013 | C42: =$F$8 -> 751.79129 | D42: =B42+C42 -> 1710.8214 | E42: =$F$7 -> 959.03013 | F42: =$F$8 -> 751.79129 | G42: =E42+F42 -> 1710.8214
A43: 2027 | B43: =$F$7 -> 959.03013 | C43: =$F$8 -> 751.79129 | D43: =B43+C43 -> 1710.8214 | E43: =$F$7 -> 959.03013 | F43: =$F$8 -> 751.79129 | G43: =E43+F43 -> 1710.8214
A44: 2028 | B44: =$F$7 -> 959.03013 | C44: =$F$8 -> 751.79129 | D44: =B44+C44 -> 1710.8214 | E44: =$F$7 -> 959.03013 | F44: =$F$8 -> 751.79129 | G44: =E44+F44 -> 1710.8214
A45: 2029 | B45: =$F$7 -> 959.03013 | C45: =$F$8 -> 751.79129 | D45: =B45+C45 -> 1710.8214 | E45: =$F$7 -> 959.03013 | F45: =$F$8 -> 751.79129 | G45: =E45+F45 -> 1710.8214
A46: 2030 | B46: =$F$7 -> 959.03013 | C46: =$F$8 -> 751.79129 | D46: =B46+C46 -> 1710.8214 | E46: =$F$7 -> 959.03013 | F46: =$F$8 -> 751.79129 | G46: =E46+F46 -> 1710.8214
...

Sheet Cash Flow
A1: MONUMENT PARAMETRIC ENGINE -- CASH FLOW
A2: STAGE A: structural Sources and Uses. Net profit (headline #4) = total non-equity inflows minus total non-distribution outflows. Intra-year timing, XIRR and MOIC are Stage B.
A3: Active scenario: | B3: =Inputs!B3 -> Base
A5: SOURCES & USES -- STAGE A
A6: Line item | B6: 2026 | C6: 2027 | D6: 2028 | E6: 2029 | F6: 2030 | G6: 2031 | H6: 2032 | I6: 2033 | J6: 2034 | K6: 2035 | L6: 2036 | M6: 2037 | N6: Total ($K) | O6: Source / note
A7: SOURCES (non-equity)
A8: Opening cash on hand | B8: =Inputs!G60 -> 5000 | C8: 0 | D8: 0 | E8: 0 | F8: 0 | G8: 0 | H8: 0 | I8: 0 | J8: 0 | K8: 0 | L8: 0 | M8: 0 | N8: =SUM(B8:M8) -> 5000 | O8: Inputs G60
A9: Developer lot real estate | B9: =Revenue!C17-Revenue!D17-Revenue!F17 -> 0 | C9: =Revenue!C18-Revenue!D18-Revenue!F18 -> 3636.4815 | D9: =Revenue!C19-Revenue!D19-Revenue!F19 -> 21818.889 | E9: =Revenue!C20-Revenue!D20-Revenue!F20 -> 27395.37 | F9: =Revenue!C21-Revenue!D21-Revenue!F21 -> 37578.333 | G9: =Revenue!C22-Revenue!D22-Revenue!F22 -> 18425.926 | H9: =Revenue!C23-Revenue!D23-Revenue!F23 -> 0 | I9: =Revenue!C24-Revenue!D24-Revenue!F24 -> 0 | J9: =Revenue!C25-Revenue!D25-Revenue!F25 -> 0 | K9: =Revenue!C26-Revenue!D26-Revenue!F26 -> 0 | L9: =Revenue!C27-Revenue!D27-Revenue!F27 -> 0 | M9: =Revenue!C28-Revenue!D28-Revenue!F28 -> 0 | N9: =SUM(B9:M9) -> 108855 | O9: Revenue: gross less commission less Foundation carve
A10: Fractional cabin sales | N10: =12000*ROUND(2*Inputs!G95,0)/2 -> 12000 | O10: Carried: team, 16 shares x $750K
A11: Foundation contributions | B11: =Foundation!C20+Inputs!G92 -> 1000 | C11: =Foundation!C21 -> 2400 | D11: =Foundation!C22 -> 7200 | E11: =Foundation!C23 -> 8400 | F11: =Foundation!C24 -> 9600 | G11: =Foundation!C25 -> 4800 | H11: =Foundation!C26 -> 0 | I11: =Foundation!C27 -> 0 | J11: =Foundation!C28 -> 0 | K11: =Foundation!C29 -> 0 | L11: =Foundation!C30 -> 0 | M11: =Foundation!C31 -> 0 | N11: =SUM(B11:M11) -> 33400 | O11: Revenue lot contributions + initial seed
A12: Foundation investment yield | B12: =Foundation!G20 -> 54.315282 | C12: =Foundation!G21 -> 108.90152 | D12: =Foundation!G22 -> 414.55765 | E12: =Foundation!G23 -> 930.28459 | F12: =Foundation!G24 -> 1546.4117 | G12: =Foundation!G25 -> 2051.4751 | H12: =Foundation!G26 -> 2233.7378 | I12: =Foundation!G27 -> 2252.7154 | J12: =Foundation!G28 -> 2271.4559 | K12: =Foundation!G29 -> 2289.8941 | L12: =Foundation!G30 -> 2307.9585 | M12: =Foundation!G31 -> 2325.5706 | N12: =SUM(B12:M12) -> 18787.278 | O12: Foundation sheet
A13: Foundation grants | B13: =Foundation!D20 -> 0 | C13: =Foundation!D21 -> 62.5 | D13: =Foundation!D22 -> 375 | E13: =Foundation!D23 -> 500 | F13: =Foundation!D24 -> 500 | G13: =Foundation!D25 -> 500 | H13: =Foundation!D26 -> 500 | I13: =Foundation!D27 -> 500 | J13: =Foundation!D28 -> 500 | K13: =Foundation!D29 -> 500 | L13: =Foundation!D30 -> 500 | M13: =Foundation!D31 -> 500 | N13: =SUM(B13:M13) -> 4937.5 | O13: Foundation sheet
A14: Initiation fees (net) | B14: =Revenue!J17 -> 0 | C14: =Revenue!J18 -> 2326.5 | D14: =Revenue!J19 -> 3663 | E14: =Revenue!J20 -> 1782 | F14: =Revenue!J21 -> 792 | G14: =Revenue!J22 -> 297 | H14: =Revenue!J23 -> 0 | I14: =Revenue!J24 -> 0 | J14: =Revenue!J25 -> 0 | K14: =Revenue!J26 -> 0 | L14: =Revenue!J27 -> 0 | M14: =Revenue!J28 -> 0 | N14: =SUM(B14:M14) -> 8860.5 | O14: Revenue sheet
A15: Club dues | B15: =Revenue!M17 -> 333.33333 | C15: =Revenue!M18 -> 490.83333 | D15: =Revenue!M19 -> 971.25 | E15: =Revenue!M20 -> 1422.5 | F15: =Revenue!M21 -> 1652.0833 | G15: =Revenue!M22 -> 1781.25 | H15: =Revenue!M23 -> 1800 | I15: =Revenue!M24 -> 1800 | J15: =Revenue!M25 -> 1800 | K15: =Revenue!M26 -> 1800 | L15: =Revenue!M27 -> 1800 | M15: =Revenue!M28 -> 1800 | N15: =SUM(B15:M15) -> 17451.25 | O15: Revenue sheet
A16: Interest on cash on hand | N16: 4008.042 | O16: Carried: team
A17: Other club revenue | N17: 6418.208 | O17: Carried: team
A18: Total Sources (non-equity) | B18: =SUM(B8:B17) -> 6387.6486 | C18: =SUM(C8:C17) -> 9025.2163 | D18: =SUM(D8:D17) -> 34442.697 | E18: =SUM(E8:E17) -> 40430.155 | F18: =SUM(F8:F17) -> 51668.828 | G18: =SUM(G8:G17) -> 27855.651 | H18: =SUM(H8:H17) -> 4533.7378 | I18: =SUM(I8:I17) -> 4552.7154 | ... N18: =SUM(N8:N17) -> 219717.78
A19: USES (non-distribution)
A20: Project & construction cost | B20: ='Development Cost'!C33 -> 2986.8828 | C20: ='Development Cost'!C34 -> 5861.397 | D20: ='Development Cost'!C35 -> 11709.044 | E20: ='Development Cost'!C36 -> 16627.983 | F20: ='Development Cost'!C37 -> 17560.519 | G20: ='Development Cost'!C38 -> 12344.646 | H20: ='Development Cost'!C39 -> 313.14365 | I20: ='Development Cost'!C40 -> 0 | J20: ='Development Cost'!C41 -> 0 | K20: ='Development Cost'!C42 -> 0 | L20: ='Development Cost'!C43 -> 0 | M20: ='Development Cost'!C44 -> 0 | N20: =SUM(B20:M20) -> 67403.615 | O20: Development Cost sheet
A21: Pre-development | N21: =Inputs!G93 -> 3914.59 | O21: Inputs G93 (fixed)
A22: Sales & marketing | N22: =Inputs!G94*Revenue!C29 -> 1122.9999 | O22: Inputs G94 x gross RE (0.77pct)
A23: Cabin construction | N23: =28559*Inputs!G95 -> 28559 | O23: Carried: team, 10 cabins
A24: Club operating expense | N24: =43096.393 * (0.7 + 0.3 * (Inputs!G73 + Inputs!G74) / 92) -> 43096.393 | O24: Carried: team
A25: Club equipment | N25: 2382.29 | O25: Carried: team
A26: Pre-existing debt service | B26: =Debt!D42 -> 1710.8214 | C26: =Debt!D43 -> 1710.8214 | D26: =Debt!D44 -> 1710.8214 | E26: =Debt!D45 -> 1710.8214 | F26: =Debt!D46 -> 1710.8214 | G26: =Debt!D47 -> 1710.8214 | H26: =Debt!D48 -> 20376.704 | I26: =Debt!D49 -> 0 | J26: =Debt!D50 -> 0 | K26: =Debt!D51 -> 0 | L26: =Debt!D52 -> 0 | M26: =Debt!D53 -> 0 | N26: =SUM(B26:M26) -> 30641.632 | O26: Debt sheet, retire path
A27: Construction debt interest | N27: 1140.456 | O27: Carried: team
A28: Foundation end balance | N28: =Foundation!H31 -> 33348.428 | O28: Foundation sheet (locked, not distributed)
A29: Total Uses (non-distribution) | B29: =SUM(B20:B28) -> 4697.7042 | C29: =SUM(C20:C28) -> 7572.2184 | D29: =SUM(D20:D28) -> 13419.865 | E29: =SUM(E20:E28) -> 18338.805 | F29: =SUM(F20:F28) -> 19271.34 | G29: =SUM(G20:G28) -> 14055.468 | H29: =SUM(H20:H28) -> 20689.847 | I29: =SUM(I20:I28) -> 0 | ... N29: =SUM(N20:N28) -> 211609.4
A31: NET PROFIT -- HEADLINE #4
A32: Net profit (engine) | N32: =N18-N29 -> 8108.3737
A33: Team net profit | N33: 7915.17
A34: Delta (engine - team) | N34: =N32-N33 -> 193.20366
A35: Delta is the propagated Sheet-6 debt residual (-$193.6K within Debt tolerance, +$193.6K here). Accepted per the Reconciliation Framework: traced, single-source, documented.
A37: STAGE B -- EQUITY CASH FLOW, XIRR, MOIC
A38: New-equity cash flow. Equity contributed during construction (2026-2027, team split); distributions follow the team post-revolver-repayment sequence (balloon aligned to 2031 per Base convention); distribution amounts are the engine reconciled distributable cash. Columns B and C are calibration constants from the team annual cash flow.
A40: Total distributable to equity ($K) | B40: =N32+10000 -> 18108.374
A41: Team total distribution ($K) | B41: 17915.17
A42: Engine / team scale factor | B42: =B40/B41 -> 1.0107844
A44: Year | B44: Equity contribution | C44: Team dist timing | D44: Distribution (engine) | E44: Net equity cash flow | F44: Date
A45: 2026 | B45: 6317.89 | C45: 0 | D45: =C45*$B$42 -> 0 | E45: =D45-B45 -> -6317.89 | F45: =DATE(2026,12,31) -> 46387
...

Sheet Peak Funding
A1: MONUMENT PARAMETRIC ENGINE -- PEAK FUNDING REQUIREMENT
A2: Monthly cash-position sub-model. Peak Funding Requirement = depth of the cumulative cash trough. Engine body stays annual; this sheet feeds the funding metric only. Revenue at team close months; costs spread monthly. Cabin construction at team timing (months 45-68).
A3: Active scenario: | B3: =Inputs!B3 -> Base
A5: PARAMETERS
A6: Opening cash on hand ($K) | B6: =Inputs!G60 -> 5000
A7: Revolver limit ($K) | B7: =Inputs!G59 -> 10000
A8: New equity raise ($K) | B8: =Inputs!G58 -> 10000
A9: Revenue scale (scenario / Base) | B9: =(Revenue!C29-Revenue!D29-Revenue!F29)/108855 -> 1
A10: Construction scale (scenario / Base) | B10: =('Development Cost'!B26)/67403.6 -> 1
A12: RESULT
A13: Peak Funding Requirement ($K) | B13: =MAX(0,-MIN(G17:G100)) -> 8929.2512
A14: Idle equity ($K) = raise - PFR | B14: =B8-B13 -> 1070.7488
A15: Status vs $20M capacity | B15: =IF(B13>20000,"UNDERCAPITALIZED: shortfall "&TEXT(B13-20000,"#,##0"),"within $20M revolver+equity capacity") -> within $20M revolver+equity capacity
A16: Month | B16: Year | C16: Dev RE base | D16: Construction base | E16: Other net base | F16: Monthly net | G16: Cumulative
A17: 1 | B17: 2026 | C17: 0 | D17: 193.354 | E17: -307.697 | F17: =C17*$B$9-D17*$B$10+E17 -> -501.05101 | G17: =$B$6+F17 -> 4498.949
A18: 2 | B18: 2026 | C18: 0 | D18: 193.354 | E18: -307.697 | F18: =C18*$B$9-D18*$B$10+E18 -> -501.05101 | G18: =G17+F18 -> 3997.898
A19: 3 | B19: 2026 | C19: 0 | D19: 193.354 | E19: -307.697 | F19: =C19*$B$9-D19*$B$10+E19 -> -501.05101 | G19: =G18+F19 -> 3496.847
A20: 4 | B20: 2026 | C20: 0 | D20: 193.354 | E20: -307.697 | F20: =C20*$B$9-D20*$B$10+E20 -> -501.05101 | G20: =G19+F20 -> 2995.796
A21: 5 | B21: 2026 | C21: 0 | D21: 193.354 | E21: -307.697 | F21: =C21*$B$9-D21*$B$10+E21 -> -501.05101 | G21: =G20+F21 -> 2494.745
A22: 6 | B22: 2026 | C22: 0 | D22: 193.354 | E22: -307.697 | F22: =C22*$B$9-D22*$B$10+E22 -> -501.05101 | G22: =G21+F22 -> 1993.694
A23: 7 | B23: 2026 | C23: 0 | D23: 193.354 | E23: -307.697 | F23: =C23*$B$9-D23*$B$10+E23 -> -501.05101 | G23: =G22+F23 -> 1492.643
A24: 8 | B24: 2026 | C24: 0 | D24: 193.354 | E24: -307.697 | F24: =C24*$B$9-D24*$B$10+E24 -> -501.05101 | G24: =G23+F24 -> 991.59196
A25: 9 | B25: 2026 | C25: 0 | D25: 193.354 | E25: -307.697 | F25: =C25*$B$9-D25*$B$10+E25 -> -501.05101 | G25: =G24+F25 -> 490.54095
A26: 10 | B26: 2026 | C26: 0 | D26: 193.354 | E26: -307.697 | F26: =C26*$B$9-D26*$B$10+E26 -> -501.05101 | G26: =G25+F26 -> -10.510052
A27: 11 | B27: 2026 | C27: 0 | D27: 193.354 | E27: -307.697 | F27: =C27*$B$9-D27*$B$10+E27 -> -501.05101 | G27: =G26+F27 -> -511.56106
A28: 12 | B28: 2027 | C28: 0 | D28: 598.218 | E28: -243.551 | F28: =C28*$B$9-D28*$B$10+E28 -> -841.76902 | G28: =G27+F28 -> -1353.3301
A29: 13 | B29: 2027 | C29: 0 | D29: 598.218 | E29: -243.551 | F29: =C29*$B$9-D29*$B$10+E29 -> -841.76902 | G29: =G28+F29 -> -2195.0991
... A100: 84 | B100: 2032 | C100: 0 | D100: 39.102 | E100: 80.09 | F100: =C100*$B$9-D100*$B$10+E100 -> 40.987999 | G100: =G99+F100 -> 9266.9282

Sheet Reconciliation
A1: MONUMENT PARAMETRIC ENGINE -- RECONCILIATION
A2: Validation dashboard. Engine outputs vs the team pro forma at Base Case inputs. No calculation happens here; every engine value is pulled live from the calculation sheets.
A3: Active scenario: | B3: =Inputs!B3 -> Base | D3: Reconciliation is defined at Base Case. With the dropdown on Base, the engine reproduces the team numbers as shown. Other scenarios have no team comparator.
A5: RECONCILIATION FRAMEWORK
A6: The engine reconciles to the team six headline numbers at Base Case inputs. Three reconcile exactly or near-exactly (real estate revenue, levered XIRR, pre-existing debt service, plus the Foundation end balance). Three (net profit, MOIC, and the residual visible in XIRR) carry a single propagated residual that originates in the pre-existing debt service calculation, which itself reconciles within its own tolerance. The pre-existing debt is built from stated loan terms by PMT; the team implied payment runs about $23K per year higher, unexplained, plausibly fees or a land-contract premium. That residual propagates downstream because net profit is a smaller number with a tighter tolerance. The propagation is documented and traced to a single source; the engine introduces no compensating adjustments to mask it. See ENGINE_CHANGELOG.md, section Reconciliation Framework, for full detail.
A8: SIX-NUMBER RECONCILIATION -- BASE CASE
A9: Headline | B9: Engine | C9: Team | D9: Delta | E9: Tolerance | F9: Status | G9: Note
A10: 1 Total real estate revenue ($K) | B10: =Revenue!C29 -> 146000 | C10: 146000 | D10: =B10-C10 -> 0 | E10: +/- 1% | F10: PASS (exact) | G10: Gross lot sales, 27 lots
A11: 2 Levered XIRR (new equity) | B11: ='Cash Flow'!B59 -> 0.16247286 | C11: 0.162 | D11: =B11-C11 -> 0.00047286201 | E11: +/- 16 bps | F11: PASS (+4.7 bps) | G11: Within tolerance; carries propagated residual lightly (late-year discounting)
A12: 3 MOIC (new equity) | B12: ='Cash Flow'!B60 -> 1.8108374 | C12: 1.792 | D12: =B12-C12 -> 0.018837366 | E12: +/- 0.018 | F12: ACCEPTED (framework) | G12: Propagated debt residual: MOIC = 1 + net profit / equity
A13: 4 Net profit ($K) | B13: ='Cash Flow'!N32 -> 8108.3737 | C13: 7915.17 | D13: =B13-C13 -> 193.20366 | E13: +/- $79K | F13: ACCEPTED (framework) | G13: Propagated debt residual, single source, documented
A14: 5 Foundation end balance 2037 ($K) | B14: =Foundation!H31 -> 33348.428 | C14: 33525.16 | D14: =B14-C14 -> -176.73185 | E14: +/- $335K | F14: PASS | G14: Annual-vs-monthly approximation, within tolerance
A15: 6 Pre-existing debt service ($K) | B15: =Debt!B57 -> 30641.632 | C15: 30835.21 | D15: =B15-C15 -> -193.57782 | E15: +/- $310K | F15: PASS | G15: PMT from stated terms; team implied payment ~$23K/yr higher
A17: WHAT TO LOOK AT -- ORIENTATION FOR A FIRST-TIME READER
A18: Inputs sheet: every parametric control. The scenario dropdown is cell B3; the live value of each input is column G. Yellow cells are the Custom scenario inputs; light green is engine-built.
A19: Reconciliation sheet (this one): the six-number validation dashboard. It confirms the engine reproduces the team pro forma at Base Case.
A20: ENGINE_CHANGELOG.md (in the project folder): the full audit trail. Every modeling decision, every residual, every convention, written for a skeptical partner.
A21: Calculation order: Inputs feeds Lot Schedule, then Revenue, Development Cost, Foundation, and Debt, which feed Cash Flow, which lands here. Each sheet reads the one before it; nothing reads backward.
